Workbook

Sheet Order Form
B2: Customer Name: | I2: Order Date: | J2: =TODAY() -> 46137
B3: Company Name: | C3: Signature Shades | I3: Date Required By:
B4: Address: | I4: Total Curtains: | J4: =COUNT(C11:C30) -> 7
B5: Phone: | I5: Total Curtain Meteres | J5: =SUM(C11:C30)/1000 -> 24.096
A10: No | B10: Location | C10: Width | D10: Drop | E10: Deducted size | F10: Curtain Type | G10: Hem | H10: Fabric | I10: Colour | J10: Installation | K10: Bracket Type | L10: Track Colour | M10: Opening Type | N10: Wand Size | O10: Fullness | P10: Notes | S10: 13
A11: {=_xlfn.SEQUENCE(COUNTA(B12:B30)+1,1,1)} -> 1 | B11: B1 | C11: 3060 | D11: 2333 | E11: =IF(ISBLANK(D11),"",D11-30) -> 2303 | F11: S Fold | G11: 70 mm | H11: Bali | I11: Pearl | J11: Wall | K11: Standard | L11: White | M11: Centre Open | N11: 1000 | O11: 120 Fullness | S11: 15
A12: 2 | B12: B2 | C12: 3194 | D12: 2330 | E12: =IF(ISBLANK(D12),"",D12-30) -> 2300 | F12: S Fold | G12: 70 mm | H12: Bali | I12: Pearl | J12: Wall | K12: Standard | L12: White | M12: Centre Open | N12: 1000 | O12: 140 Fullness | S12: 11
A13: 3 | B13: B3 | C13: 2692 | D13: 2330 | E13: =IF(ISBLANK(D13),"",D13-30) -> 2300 | F13: S Fold | G13: 70 mm | H13: Bali | I13: Pearl | J13: Wall | K13: Standard | L13: White | M13: Centre Open | N13: 1000 | O13: 144 Fullness | S13: 14
A14: 4 | B14: Master | C14: 3165 | D14: 2331 | E14: =IF(ISBLANK(D14),"",D14-30) -> 2301 | F14: S Fold | G14: 70 mm | H14: Bali | I14: flax | J14: Wall | K14: Standard | L14: White | M14: Centre Open | N14: 1000 | O14: 120 Fullness | S14: 14
A15: 5 | B15: L1 | C15: 5428 | D15: 2329 | E15: =IF(ISBLANK(D15),"",D15-30) -> 2299 | F15: S Fold | G15: 70 mm | H15: Bali | I15: Pearl | J15: Wall | K15: Standard | L15: White | M15: Single Open | N15: 1000 | O15: 140 Fullness | S15: 8
A16: 6 | B16: Tv L | C16: 3180 | D16: 2380 | E16: =IF(ISBLANK(D16),"",D16-30) -> 2350 | F16: S Fold | G16: 70 mm | H16: Bali | I16: Pearl | J16: Wall | K16: Standard | L16: White | M16: Single Open | N16: 1000 | O16: 144 Fullness | S16: 27
A17: 7 | B17: Tv R | C17: 3377 | D17: 2380 | E17: =IF(ISBLANK(D17),"",D17-30) -> 2350 | F17: S Fold | G17: 70 mm | H17: Bali | I17: Pearl | J17: Wall | K17: Standard | L17: White | M17: Single Open | N17: 1000 | O17: 120 Fullness | S17: 15
S18: 13
S19: 2
S20: 1
S21: 17
S22: 7
S23: 12
S24: 4
S25: 11
S26: 5
S27: 26
S28: 9
S29: 1
... S37: 8

Sheet Indetail CAL
A2: No | B2: Location | C2: width | D2: Standard | E2: Extended | F2: wand | G2: Single hooks | H2: Left Side Hook | I2: Right Side Hooks | J2: Total Hooks | K2: Fabric
A3: 1 | B3: =IF('Order Form'!B11=0,"",'Order Form'!B11) -> B1 | C3: ='Order Form'!C11 -> 3060 | D3: =IF('Order Form'!K11="Standard",(IFERROR(VLOOKUP($C3,$S$43:$T$52,2),"")),"") -> 5 | E3: =IF('Order Form'!K11="Extended",(IFERROR(VLOOKUP($C3,$S$43:$T$52,2),"")),"") | F3: =IF(ISBLANK('Order Form'!$M11),"",IF('Order Form'!$M11="Centre Open",2,1)) -> 2 | G3: =IF('Order Form'!$M11="Single Open",VLOOKUP(Table3[[#This Row],[width]],'VLOOK Hooks'!$C$3:$F$539,4,TRUE),"") | H3: =IF('Order Form'!$M11="Centre Open",VLOOKUP((Table3[[#This Row],[width]]/2),'VLOOK Hooks'!$C$3:$F$539,4,TRUE),"") -> 30 | I3: =IF('Order Form'!$M11="Centre Open",VLOOKUP((Table3[[#This Row],[width]]/2),'VLOOK Hooks'!$C$3:$F$539,4,TRUE),"") -> 30 | J3: =SUM(Table3[[#This Row],[Single hooks]:[Right Side Hooks]]) -> 60 | K3: =IF('Order Form'!$M11="Single Open",((Table3[[#This Row],[Single hooks]]*120)+140),IF('Order Form'!$M11="Centre Open",(((Table3[[#This Row],[Left Side Hook]]+Table3[[#This Row],[Right Side Hooks]])*120)+280),"")) -> 7480
A4: 2 | B4: =IF('Order Form'!B12=0,"",'Order Form'!B12) -> B2 | C4: ='Order Form'!C12 -> 3194 | D4: =IF('Order Form'!K12="Standard",(IFERROR(VLOOKUP($C4,$S$43:$T$52,2),"")),"") -> 5 | E4: =IF('Order Form'!K12="Extended",(IFERROR(VLOOKUP($C4,$S$43:$T$52,2),"")),"") | F4: =IF(ISBLANK('Order Form'!$M12),"",IF('Order Form'!$M12="Centre Open",2,1)) -> 2 | G4: =IF('Order Form'!$M12="Single Open",VLOOKUP(Table3[[#This Row],[width]],'VLOOK Hooks'!$C$3:$F$539,4,TRUE),"") | H4: =IF('Order Form'!$M12="Centre Open",VLOOKUP((Table3[[#This Row],[width]]/2),'VLOOK Hooks'!$C$3:$F$539,4,TRUE),"") -> 30 | I4: =IF('Order Form'!$M12="Centre Open",VLOOKUP((Table3[[#This Row],[width]]/2),'VLOOK Hooks'!$C$3:$F$539,4,TRUE),"") -> 30 | J4: =SUM(Table3[[#This Row],[Single hooks]:[Right Side Hooks]]) -> 60 | K4: =IF('Order Form'!$M12="Single Open",((Table3[[#This Row],[Single hooks]]*120)+140),IF('Order Form'!$M12="Centre Open",(((Table3[[#This Row],[Left Side Hook]]+Table3[[#This Row],[Right Side Hooks]])*120)+280),"")) -> 7480
A5: 3 | B5: =IF('Order Form'!B13=0,"",'Order Form'!B13) -> B3 | C5: ='Order Form'!C13 -> 2692 | D5: =IF('Order Form'!K13="Standard",(IFERROR(VLOOKUP($C5,$S$43:$T$52,2),"")),"") -> 4 | E5: =IF('Order Form'!K13="Extended",(IFERROR(VLOOKUP($C5,$S$43:$T$52,2),"")),"") | F5: =IF(ISBLANK('Order Form'!$M13),"",IF('Order Form'!$M13="Centre Open",2,1)) -> 2 | G5: =IF('Order Form'!$M13="Single Open",VLOOKUP(Table3[[#This Row],[width]],'VLOOK Hooks'!$C$3:$F$539,4,TRUE),"") | H5: =IF('Order Form'!$M13="Centre Open",VLOOKUP((Table3[[#This Row],[width]]/2),'VLOOK Hooks'!$C$3:$F$539,4,TRUE),"") -> 26 | I5: =IF('Order Form'!$M13="Centre Open",VLOOKUP((Table3[[#This Row],[width]]/2),'VLOOK Hooks'!$C$3:$F$539,4,TRUE),"") -> 26 | J5: =SUM(Table3[[#This Row],[Single hooks]:[Right Side Hooks]]) -> 52 | K5: =IF('Order Form'!$M13="Single Open",((Table3[[#This Row],[Single hooks]]*120)+140),IF('Order Form'!$M13="Centre Open",(((Table3[[#This Row],[Left Side Hook]]+Table3[[#This Row],[Right Side Hooks]])*120)+280),"")) -> 6520
A6: 4 | B6: =IF('Order Form'!B14=0,"",'Order Form'!B14) -> Master | C6: ='Order Form'!C14 -> 3165 | D6: =IF('Order Form'!K14="Standard",(IFERROR(VLOOKUP($C6,$S$43:$T$52,2),"")),"") -> 5 | E6: =IF('Order Form'!K14="Extended",(IFERROR(VLOOKUP($C6,$S$43:$T$52,2),"")),"") | F6: =IF(ISBLANK('Order Form'!$M14),"",IF('Order Form'!$M14="Centre Open",2,1)) -> 2 | G6: =IF('Order Form'!$M14="Single Open",VLOOKUP(Table3[[#This Row],[width]],'VLOOK Hooks'!$C$3:$F$539,4,TRUE),"") | H6: =IF('Order Form'!$M14="Centre Open",VLOOKUP((Table3[[#This Row],[width]]/2),'VLOOK Hooks'!$C$3:$F$539,4,TRUE),"") -> 30 | I6: =IF('Order Form'!$M14="Centre Open",VLOOKUP((Table3[[#This Row],[width]]/2),'VLOOK Hooks'!$C$3:$F$539,4,TRUE),"") -> 30 | J6: =SUM(Table3[[#This Row],[Single hooks]:[Right Side Hooks]]) -> 60 | K6: =IF('Order Form'!$M14="Single Open",((Table3[[#This Row],[Single hooks]]*120)+140),IF('Order Form'!$M14="Centre Open",(((Table3[[#This Row],[Left Side Hook]]+Table3[[#This Row],[Right Side Hooks]])*120)+280),"")) -> 7480
A7: 5 | B7: =IF('Order Form'!B15=0,"",'Order Form'!B15) -> L1 | C7: ='Order Form'!C15 -> 5428 | D7: =IF('Order Form'!K15="Standard",(IFERROR(VLOOKUP($C7,$S$43:$T$52,2),"")),"") -> 7 | E7: =IF('Order Form'!K15="Extended",(IFERROR(VLOOKUP($C7,$S$43:$T$52,2),"")),"") | F7: =IF(ISBLANK('Order Form'!$M15),"",IF('Order Form'!$M15="Centre Open",2,1)) -> 1 | G7: =IF('Order Form'!$M15="Single Open",VLOOKUP(Table3[[#This Row],[width]],'VLOOK Hooks'!$C$3:$F$539,4,TRUE),"") -> 102 | H7: =IF('Order Form'!$M15="Centre Open",VLOOKUP((Table3[[#This Row],[width]]/2),'VLOOK Hooks'!$C$3:$F$539,4,TRUE),"") | I7: =IF('Order Form'!$M15="Centre Open",VLOOKUP((Table3[[#This Row],[width]]/2),'VLOOK Hooks'!$C$3:$F$539,4,TRUE),"") | J7: =SUM(Table3[[#This Row],[Single hooks]:[Right Side Hooks]]) -> 102 | K7: =IF('Order Form'!$M15="Single Open",((Table3[[#This Row],[Single hooks]]*120)+140),IF('Order Form'!$M15="Centre Open",(((Table3[[#This Row],[Left Side Hook]]+Table3[[#This Row],[Right Side Hooks]])*120)+280),"")) -> 12380
A8: 6 | B8: =IF('Order Form'!B16=0,"",'Order Form'!B16) -> Tv L | C8: ='Order Form'!C16 -> 3180 | D8: =IF('Order Form'!K16="Standard",(IFERROR(VLOOKUP($C8,$S$43:$T$52,2),"")),"") -> 5 | E8: =IF('Order Form'!K16="Extended",(IFERROR(VLOOKUP($C8,$S$43:$T$52,2),"")),"") | F8: =IF(ISBLANK('Order Form'!$M16),"",IF('Order Form'!$M16="Centre Open",2,1)) -> 1 | G8: =IF('Order Form'!$M16="Single Open",VLOOKUP(Table3[[#This Row],[width]],'VLOOK Hooks'!$C$3:$F$539,4,TRUE),"") -> 60 | H8: =IF('Order Form'!$M16="Centre Open",VLOOKUP((Table3[[#This Row],[width]]/2),'VLOOK Hooks'!$C$3:$F$539,4,TRUE),"") | I8: =IF('Order Form'!$M16="Centre Open",VLOOKUP((Table3[[#This Row],[width]]/2),'VLOOK Hooks'!$C$3:$F$539,4,TRUE),"") | J8: =SUM(Table3[[#This Row],[Single hooks]:[Right Side Hooks]]) -> 60 | K8: =IF('Order Form'!$M16="Single Open",((Table3[[#This Row],[Single hooks]]*120)+140),IF('Order Form'!$M16="Centre Open",(((Table3[[#This Row],[Left Side Hook]]+Table3[[#This Row],[Right Side Hooks]])*120)+280),"")) -> 7340
A9: 7 | B9: =IF('Order Form'!B17=0,"",'Order Form'!B17) -> Tv R | C9: ='Order Form'!C17 -> 3377 | D9: =IF('Order Form'!K17="Standard",(IFERROR(VLOOKUP($C9,$S$43:$T$52,2),"")),"") -> 5 | E9: =IF('Order Form'!K17="Extended",(IFERROR(VLOOKUP($C9,$S$43:$T$52,2),"")),"") | F9: =IF(ISBLANK('Order Form'!$M17),"",IF('Order Form'!$M17="Centre Open",2,1)) -> 1 | G9: =IF('Order Form'!$M17="Single Open",VLOOKUP(Table3[[#This Row],[width]],'VLOOK Hooks'!$C$3:$F$539,4,TRUE),"") -> 64 | H9: =IF('Order Form'!$M17="Centre Open",VLOOKUP((Table3[[#This Row],[width]]/2),'VLOOK Hooks'!$C$3:$F$539,4,TRUE),"") | I9: =IF('Order Form'!$M17="Centre Open",VLOOKUP((Table3[[#This Row],[width]]/2),'VLOOK Hooks'!$C$3:$F$539,4,TRUE),"") | J9: =SUM(Table3[[#This Row],[Single hooks]:[Right Side Hooks]]) -> 64 | K9: =IF('Order Form'!$M17="Single Open",((Table3[[#This Row],[Single hooks]]*120)+140),IF('Order Form'!$M17="Centre Open",(((Table3[[#This Row],[Left Side Hook]]+Table3[[#This Row],[Right Side Hooks]])*120)+280),"")) -> 7820
A10: 8 | B10: =IF('Order Form'!B18=0,"",'Order Form'!B18) | C10: ='Order Form'!C18 -> 0 | D10: =IF('Order Form'!K18="Standard",(IFERROR(VLOOKUP($C10,$S$43:$T$52,2),"")),"") | E10: =IF('Order Form'!K18="Extended",(IFERROR(VLOOKUP($C10,$S$43:$T$52,2),"")),"") | F10: =IF(ISBLANK('Order Form'!$M18),"",IF('Order Form'!$M18="Centre Open",2,1)) | G10: =IF('Order Form'!$M18="Single Open",VLOOKUP(Table3[[#This Row],[width]],'VLOOK Hooks'!$C$3:$F$539,4,TRUE),"") | H10: =IF('Order Form'!$M18="Centre Open",VLOOKUP((Table3[[#This Row],[width]]/2),'VLOOK Hooks'!$C$3:$F$539,4,TRUE),"") | I10: =IF('Order Form'!$M18="Centre Open",VLOOKUP((Table3[[#This Row],[width]]/2),'VLOOK Hooks'!$C$3:$F$539,4,TRUE),"") | J10: =SUM(Table3[[#This Row],[Single hooks]:[Right Side Hooks]]) -> 0 | K10: =IF('Order Form'!$M18="Single Open",((Table3[[#This Row],[Single hooks]]*120)+140),IF('Order Form'!$M18="Centre Open",(((Table3[[#This Row],[Left Side Hook]]+Table3[[#This Row],[Right Side Hooks]])*120)+280),""))
A11: 9 | B11: =IF('Order Form'!B19=0,"",'Order Form'!B19) | C11: ='Order Form'!C19 -> 0 | D11: =IF('Order Form'!K19="Standard",(IFERROR(VLOOKUP($C11,$S$43:$T$52,2),"")),"") | E11: =IF('Order Form'!K19="Extended",(IFERROR(VLOOKUP($C11,$S$43:$T$52,2),"")),"") | F11: =IF(ISBLANK('Order Form'!$M19),"",IF('Order Form'!$M19="Centre Open",2,1)) | G11: =IF('Order Form'!$M19="Single Open",VLOOKUP(Table3[[#This Row],[width]],'VLOOK Hooks'!$C$3:$F$539,4,TRUE),"") | H11: =IF('Order Form'!$M19="Centre Open",VLOOKUP((Table3[[#This Row],[width]]/2),'VLOOK Hooks'!$C$3:$F$539,4,TRUE),"") | I11: =IF('Order Form'!$M19="Centre Open",VLOOKUP((Table3[[#This Row],[width]]/2),'VLOOK Hooks'!$C$3:$F$539,4,TRUE),"") | J11: =SUM(Table3[[#This Row],[Single hooks]:[Right Side Hooks]]) -> 0 | K11: =IF('Order Form'!$M19="Single Open",((Table3[[#This Row],[Single hooks]]*120)+140),IF('Order Form'!$M19="Centre Open",(((Table3[[#This Row],[Left Side Hook]]+Table3[[#This Row],[Right Side Hooks]])*120)+280),""))
A12: 10 | B12: =IF('Order Form'!B20=0,"",'Order Form'!B20) | C12: ='Order Form'!C20 -> 0 | D12: =IF('Order Form'!K20="Standard",(IFERROR(VLOOKUP($C12,$S$43:$T$52,2),"")),"") | E12: =IF('Order Form'!K20="Extended",(IFERROR(VLOOKUP($C12,$S$43:$T$52,2),"")),"") | F12: =IF(ISBLANK('Order Form'!$M20),"",IF('Order Form'!$M20="Centre Open",2,1)) | G12: =IF('Order Form'!$M20="Single Open",VLOOKUP(Table3[[#This Row],[width]],'VLOOK Hooks'!$C$3:$F$539,4,TRUE),"") | H12: =IF('Order Form'!$M20="Centre Open",VLOOKUP((Table3[[#This Row],[width]]/2),'VLOOK Hooks'!$C$3:$F$539,4,TRUE),"") | I12: =IF('Order Form'!$M20="Centre Open",VLOOKUP((Table3[[#This Row],[width]]/2),'VLOOK Hooks'!$C$3:$F$539,4,TRUE),"") | J12: =SUM(Table3[[#This Row],[Single hooks]:[Right Side Hooks]]) -> 0 | K12: =IF('Order Form'!$M20="Single Open",((Table3[[#This Row],[Single hooks]]*120)+140),IF('Order Form'!$M20="Centre Open",(((Table3[[#This Row],[Left Side Hook]]+Table3[[#This Row],[Right Side Hooks]])*120)+280),""))
A13: 11 | B13: =IF('Order Form'!B21=0,"",'Order Form'!B21) | C13: ='Order Form'!C21 -> 0 | D13: =IF('Order Form'!K21="Standard",(IFERROR(VLOOKUP($C13,$S$43:$T$52,2),"")),"") | E13: =IF('Order Form'!K21="Extended",(IFERROR(VLOOKUP($C13,$S$43:$T$52,2),"")),"") | F13: =IF(ISBLANK('Order Form'!$M21),"",IF('Order Form'!$M21="Centre Open",2,1)) | G13: =IF('Order Form'!$M21="Single Open",VLOOKUP(Table3[[#This Row],[width]],'VLOOK Hooks'!$C$3:$F$539,4,TRUE),"") | H13: =IF('Order Form'!$M21="Centre Open",VLOOKUP((Table3[[#This Row],[width]]/2),'VLOOK Hooks'!$C$3:$F$539,4,TRUE),"") | I13: =IF('Order Form'!$M21="Centre Open",VLOOKUP((Table3[[#This Row],[width]]/2),'VLOOK Hooks'!$C$3:$F$539,4,TRUE),"") | J13: =SUM(Table3[[#This Row],[Single hooks]:[Right Side Hooks]]) -> 0 | K13: =IF('Order Form'!$M21="Single Open",((Table3[[#This Row],[Single hooks]]*120)+140),IF('Order Form'!$M21="Centre Open",(((Table3[[#This Row],[Left Side Hook]]+Table3[[#This Row],[Right Side Hooks]])*120)+280),""))
A14: 12 | B14: =IF('Order Form'!B22=0,"",'Order Form'!B22) | C14: ='Order Form'!C22 -> 0 | D14: =IF('Order Form'!K22="Standard",(IFERROR(VLOOKUP($C14,$S$43:$T$52,2),"")),"") | E14: =IF('Order Form'!K22="Extended",(IFERROR(VLOOKUP($C14,$S$43:$T$52,2),"")),"") | F14: =IF(ISBLANK('Order Form'!$M22),"",IF('Order Form'!$M22="Centre Open",2,1)) | G14: =IF('Order Form'!$M22="Single Open",VLOOKUP(Table3[[#This Row],[width]],'VLOOK Hooks'!$C$3:$F$539,4,TRUE),"") | H14: =IF('Order Form'!$M22="Centre Open",VLOOKUP((Table3[[#This Row],[width]]/2),'VLOOK Hooks'!$C$3:$F$539,4,TRUE),"") | I14: =IF('Order Form'!$M22="Centre Open",VLOOKUP((Table3[[#This Row],[width]]/2),'VLOOK Hooks'!$C$3:$F$539,4,TRUE),"") | J14: =SUM(Table3[[#This Row],[Single hooks]:[Right Side Hooks]]) -> 0 | K14: =IF('Order Form'!$M22="Single Open",((Table3[[#This Row],[Single hooks]]*120)+140),IF('Order Form'!$M22="Centre Open",(((Table3[[#This Row],[Left Side Hook]]+Table3[[#This Row],[Right Side Hooks]])*120)+280),""))
... A38: 36 | B38: =IF('Order Form'!B46=0,"",'Order Form'!B46) | C38: ='Order Form'!C46 -> 0 | D38: =IF('Order Form'!K46="Standard",(IFERROR(VLOOKUP($C38,$S$43:$T$52,2),"")),"") | E38: =IF('Order Form'!K46="Extended",(IFERROR(VLOOKUP($C38,$S$43:$T$52,2),"")),"") | F38: =IF(ISBLANK('Order Form'!$M46),"",IF('Order Form'!$M46="Centre Open",2,1)) | G38: =IF('Order Form'!$M46="Single Open",VLOOKUP(Table3[[#This Row],[width]],'VLOOK Hooks'!$C$3:$F$539,4,TRUE),"") | H38: =IF('Order Form'!$M46="Centre Open",VLOOKUP((Table3[[#This Row],[width]]/2),'VLOOK Hooks'!$C$3:$F$539,4,TRUE),"") | I38: =IF('Order Form'!$M46="Centre Open",VLOOKUP((Table3[[#This Row],[width]]/2),'VLOOK Hooks'!$C$3:$F$539,4,TRUE),"") | J38: =SUM(Table3[[#This Row],[Single hooks]:[Right Side Hooks]]) -> 0 | K38: =IF('Order Form'!$M46="Single Open",((Table3[[#This Row],[Single hooks]]*120)+140),IF('Order Form'!$M46="Centre Open",(((Table3[[#This Row],[Left Side Hook]]+Table3[[#This Row],[Right Side Hooks]])*120)+280),""))
D39: =SUM(Table3[Standard]) -> 36 | E39: =SUM(Table3[Extended]) -> 0 | F39: =SUM(Table3[wand]) -> 11 | G39: =SUM(Table3[Single hooks]) -> 226 | K39: =SUM(Table3[Fabric]) -> 56500
R43: 0-2750 | S43: 1 | T43: 4
R44: 2751-3750 | S44: 2751 | T44: 5
R45: 3751-4750 | S45: 3751 | T45: 6
R46: 4751-5750 | S46: 4751 | T46: 7
R47: 5751-6750 | S47: 5751 | T47: 8
R48: 6751-7750 | S48: 6751 | T48: 9
R49: 7751-8750 | S49: 7751 | T49: 10
R50: 8751-9750 | S50: 8751 | T50: 11
R51: 9751-10750 | S51: 9751 | T51: 12
R52: 10751-11750 | S52: 10751 | T52: 13
R58: METERS | S58: mm | T58: No of BRACKETS
R59: 2 | S59: =1000*R59 -> 2000 | T59: 4
R60: 2.25 | S60: =1000*R60 -> 2250 | T60: 4
R61: 2.5 | S61: =1000*R61 -> 2500 | T61: 4
R62: 2.75 | S62: =1000*R62 -> 2750 | T62: 4
R63: 3 | S63: =1000*R63 -> 3000 | T63: 5
R64: 3.25 | S64: =1000*R64 -> 3250 | T64: 5
R65: 3.5 | S65: =1000*R65 -> 3500 | T65: 5
R66: 3.75 | S66: =1000*R66 -> 3750 | T66: 5
R67: 4 | S67: =1000*R67 -> 4000 | T67: 6
R68: 4.25 | S68: =1000*R68 -> 4250 | T68: 6
R69: 4.5 | S69: =1000*R69 -> 4500 | T69: 6
R70: 4.75 | S70: =1000*R70 -> 4750 | T70: 6
... R99: 12 | S99: =1000*R99 -> 12000 | T99: 14

Sheet VLOOK Hooks
C3: Width | D3: actual | E3: rounded | F3: even
C4: 450 | D4: =$C4/54 -> 8.3333333 | E4: =ROUND($C4/54,0) -> 8 | F4: =IF(ISEVEN(($E4)),$E4,EVEN($E4)) -> 8
C5: 460 | D5: =$C5/54 -> 8.5185185 | E5: =ROUND($C5/54,0) -> 9 | F5: =IF(ISEVEN(($E5)),$E5,EVEN($E5)) -> 10
C6: 470 | D6: =$C6/54 -> 8.7037037 | E6: =ROUND($C6/54,0) -> 9 | F6: =IF(ISEVEN(($E6)),$E6,EVEN($E6)) -> 10
C7: 480 | D7: =$C7/54 -> 8.8888889 | E7: =ROUND($C7/54,0) -> 9 | F7: =IF(ISEVEN(($E7)),$E7,EVEN($E7)) -> 10
C8: 490 | D8: =$C8/54 -> 9.0740741 | E8: =ROUND($C8/54,0) -> 9 | F8: =IF(ISEVEN(($E8)),$E8,EVEN($E8)) -> 10
C9: 500 | D9: =$C9/54 -> 9.2592593 | E9: =ROUND($C9/54,0) -> 9 | F9: =IF(ISEVEN(($E9)),$E9,EVEN($E9)) -> 10
C10: 510 | D10: =$C10/54 -> 9.4444444 | E10: =ROUND($C10/54,0) -> 9 | F10: =IF(ISEVEN(($E10)),$E10,EVEN($E10)) -> 10
C11: 520 | D11: =$C11/54 -> 9.6296296 | E11: =ROUND($C11/54,0) -> 10 | F11: =IF(ISEVEN(($E11)),$E11,EVEN($E11)) -> 10
C12: 530 | D12: =$C12/54 -> 9.8148148 | E12: =ROUND($C12/54,0) -> 10 | F12: =IF(ISEVEN(($E12)),$E12,EVEN($E12)) -> 10
C13: 540 | D13: =$C13/54 -> 10 | E13: =ROUND($C13/54,0) -> 10 | F13: =IF(ISEVEN(($E13)),$E13,EVEN($E13)) -> 10
C14: 550 | D14: =$C14/54 -> 10.185185 | E14: =ROUND($C14/54,0) -> 10 | F14: =IF(ISEVEN(($E14)),$E14,EVEN($E14)) -> 10
C15: 560 | D15: =$C15/54 -> 10.37037 | E15: =ROUND($C15/54,0) -> 10 | F15: =IF(ISEVEN(($E15)),$E15,EVEN($E15)) -> 10
... C34: 750 | D34: =$C34/54 -> 13.888889 | E34: =ROUND($C34/54,0) -> 14 | F34: =IF(ISEVEN(($E34)),$E34,EVEN($E34)) -> 14
C35: 760 | D35: =$C35/54 -> 14.074074 | E35: 15 | F35: =IF(ISEVEN(($E35)),$E35,EVEN($E35)) -> 16
C36: 770 | D36: =$C36/54 -> 14.259259 | E36: 15 | F36: =IF(ISEVEN(($E36)),$E36,EVEN($E36)) -> 16
C37: 780 | D37: =$C37/54 -> 14.444444 | E37: 15 | F37: =IF(ISEVEN(($E37)),$E37,EVEN($E37)) -> 16
C38: 790 | D38: =$C38/54 -> 14.62963 | E38: =ROUND($C38/54,0) -> 15 | F38: =IF(ISEVEN(($E38)),$E38,EVEN($E38)) -> 16
C39: 800 | D39: =$C39/54 -> 14.814815 | E39: =ROUND($C39/54,0) -> 15 | F39: =IF(ISEVEN(($E39)),$E39,EVEN($E39)) -> 16
C40: 810 | D40: =$C40/54 -> 15 | E40: =ROUND($C40/54,0) -> 15 | F40: =IF(ISEVEN(($E40)),$E40,EVEN($E40)) -> 16
C41: 820 | D41: =$C41/54 -> 15.185185 | E41: 15 | F41: =IF(ISEVEN(($E41)),$E41,EVEN($E41)) -> 16
C42: 830 | D42: =$C42/54 -> 15.37037 | E42: =ROUND($C42/54,0) -> 15 | F42: =IF(ISEVEN(($E42)),$E42,EVEN($E42)) -> 16
C43: 840 | D43: =$C43/54 -> 15.555556 | E43: =ROUND($C43/54,0) -> 16 | F43: =IF(ISEVEN(($E43)),$E43,EVEN($E43)) -> 16
C44: 850 | D44: =$C44/54 -> 15.740741 | E44: =ROUND($C44/54,0) -> 16 | F44: =IF(ISEVEN(($E44)),$E44,EVEN($E44)) -> 16
C45: 860 | D45: =$C45/54 -> 15.925926 | E45: =ROUND($C45/54,0) -> 16 | F45: =IF(ISEVEN(($E45)),$E45,EVEN($E45)) -> 16
C46: 870 | D46: =$C46/54 -> 16.111111 | E46: 17 | F46: =IF(ISEVEN(($E46)),$E46,EVEN($E46)) -> 18
C47: 880 | D47: =$C47/54 -> 16.296296 | E47: 17 | F47: =IF(ISEVEN(($E47)),$E47,EVEN($E47)) -> 18
C48: 890 | D48: =$C48/54 -> 16.481481 | E48: 17 | F48: =IF(ISEVEN(($E48)),$E48,EVEN($E48)) -> 18
C49: 900 | D49: =$C49/54 -> 16.666667 | E49: =ROUND($C49/54,0) -> 17 | F49: =IF(ISEVEN(($E49)),$E49,EVEN($E49)) -> 18
C50: 910 | D50: =$C50/54 -> 16.851852 | E50: =ROUND($C50/54,0) -> 17 | F50: =IF(ISEVEN(($E50)),$E50,EVEN($E50)) -> 18
C51: 920 | D51: =$C51/54 -> 17.037037 | E51: =ROUND($C51/54,0) -> 17 | F51: =IF(ISEVEN(($E51)),$E51,EVEN($E51)) -> 18
C52: 930 | D52: =$C52/54 -> 17.222222 | E52: =ROUND($C52/54,0) -> 17 | F52: =IF(ISEVEN(($E52)),$E52,EVEN($E52)) -> 18
C53: 940 | D53: =$C53/54 -> 17.407407 | E53: =ROUND($C53/54,0) -> 17 | F53: =IF(ISEVEN(($E53)),$E53,EVEN($E53)) -> 18
C54: 950 | D54: =$C54/54 -> 17.592593 | E54: =ROUND($C54/54,0) -> 18 | F54: =IF(ISEVEN(($E54)),$E54,EVEN($E54)) -> 18
C55: 960 | D55: =$C55/54 -> 17.777778 | E55: =ROUND($C55/54,0) -> 18 | F55: =IF(ISEVEN(($E55)),$E55,EVEN($E55)) -> 18
C56: 970 | D56: =$C56/54 -> 17.962963 | E56: =ROUND($C56/54,0) -> 18 | F56: =IF(ISEVEN(($E56)),$E56,EVEN($E56)) -> 18
C57: 980 | D57: =$C57/54 -> 18.148148 | E57: 20 | F57: =IF(ISEVEN(($E57)),$E57,EVEN($E57)) -> 20
C58: 990 | D58: =$C58/54 -> 18.333333 | E58: 19 | F58: =IF(ISEVEN(($E58)),$E58,EVEN($E58)) -> 20
C59: 1000 | D59: =$C59/54 -> 18.518519 | E59: =ROUND($C59/54,0) -> 19 | F59: =IF(ISEVEN(($E59)),$E59,EVEN($E59)) -> 20
C60: 1010 | D60: =$C60/54 -> 18.703704 | E60: =ROUND($C60/54,0) -> 19 | F60: =IF(ISEVEN(($E60)),$E60,EVEN($E60)) -> 20
...

Sheet Track WORKSHEET
F1: Track Colour | H1: ='Order Form'!L11 -> White
F2: No of Wands | H2: =ABS(Table3[[#Totals],[wand]]) -> 11
F3: Fabric | H3: ='Order Form'!H11 -> Bali
B4: Customer Name: | C4: ='Order Form'!C2 -> 0 | F4: Colour | H4: ='Order Form'!I11 -> Pearl
B5: Order Refferance | C5: {=MID(CELL("filename"),FIND("[",CELL("filename")),15)} -> [SHEER 2026.xls | F5: No of Hooks | H5: =SUM(FInal[[Single hooks]:[Right Side Hooks]]) -> 458
F6: No of Brackets | G6: Standard | H6: =SUM(Table3[[#Totals],[Standard]]) -> 36
G7: Extended | H7: =SUM(Table3[[#Totals],[Extended]]) -> 0
F8: Total Fabrics | H8: =ABS(Table3[[#Totals],[Fabric]]) -> 56500
A10: No | B10: Location | C10: Width | D10: Deducted Drop | E10: Opening Type | F10: Single hooks | G10: Left Side Hook | H10: Right Side Hooks | I10: Fullness | J10: Fabric
A11: 1 | B11: =IF(ISBLANK('Order Form'!$B11),"",'Order Form'!$B11) -> B1 | C11: =IF(ISBLANK('Order Form'!$C11),"",'Order Form'!$C11) -> 3060 | D11: =IF(ISBLANK('Order Form'!$E11),"",'Order Form'!$E11) -> 2303 | E11: =IF(ISBLANK('Order Form'!M11),"",'Order Form'!M11) -> Centre Open | F11: =IF(ISBLANK('Indetail CAL'!$G3),"",'Indetail CAL'!$G3) | G11: =IF(ISBLANK('Indetail CAL'!$H3),"",'Indetail CAL'!$H3) -> 30 | H11: =IF('Indetail CAL'!$I3=0,"",('Indetail CAL'!$I3)) -> 30 | I11: =IF(ISBLANK('Order Form'!$O11),"",'Order Form'!$O11) -> 120 Fullness | J11: =IF(ISBLANK('Indetail CAL'!K3),"",'Indetail CAL'!K3) -> 7480
A12: 2 | B12: =IF(ISBLANK('Order Form'!$B12),"",'Order Form'!$B12) -> B2 | C12: =IF(ISBLANK('Order Form'!$C12),"",'Order Form'!$C12) -> 3194 | D12: =IF(ISBLANK('Order Form'!$E12),"",'Order Form'!$E12) -> 2300 | E12: =IF(ISBLANK('Order Form'!M12),"",'Order Form'!M12) -> Centre Open | F12: =IF(ISBLANK('Indetail CAL'!$G4),"",'Indetail CAL'!$G4) | G12: =IF(ISBLANK('Indetail CAL'!$H4),"",'Indetail CAL'!$H4) -> 30 | H12: =IF('Indetail CAL'!$I4=0,"",('Indetail CAL'!$I4)) -> 30 | I12: =IF(ISBLANK('Order Form'!$O12),"",'Order Form'!$O12) -> 140 Fullness | J12: =IF(ISBLANK('Indetail CAL'!K4),"",'Indetail CAL'!K4) -> 7480
A13: 3 | B13: =IF(ISBLANK('Order Form'!$B13),"",'Order Form'!$B13) -> B3 | C13: =IF(ISBLANK('Order Form'!$C13),"",'Order Form'!$C13) -> 2692 | D13: =IF(ISBLANK('Order Form'!$E13),"",'Order Form'!$E13) -> 2300 | E13: =IF(ISBLANK('Order Form'!M13),"",'Order Form'!M13) -> Centre Open | F13: =IF(ISBLANK('Indetail CAL'!$G5),"",'Indetail CAL'!$G5) | G13: =IF(ISBLANK('Indetail CAL'!$H5),"",'Indetail CAL'!$H5) -> 26 | H13: =IF('Indetail CAL'!$I5=0,"",('Indetail CAL'!$I5)) -> 26 | I13: =IF(ISBLANK('Order Form'!$O13),"",'Order Form'!$O13) -> 144 Fullness | J13: =IF(ISBLANK('Indetail CAL'!K5),"",'Indetail CAL'!K5) -> 6520
A14: 4 | B14: =IF(ISBLANK('Order Form'!$B14),"",'Order Form'!$B14) -> Master | C14: =IF(ISBLANK('Order Form'!$C14),"",'Order Form'!$C14) -> 3165 | D14: =IF(ISBLANK('Order Form'!$E14),"",'Order Form'!$E14) -> 2301 | E14: =IF(ISBLANK('Order Form'!M14),"",'Order Form'!M14) -> Centre Open | F14: =IF(ISBLANK('Indetail CAL'!$G6),"",'Indetail CAL'!$G6) | G14: =IF(ISBLANK('Indetail CAL'!$H6),"",'Indetail CAL'!$H6) -> 30 | H14: =IF('Indetail CAL'!$I6=0,"",('Indetail CAL'!$I6)) -> 30 | I14: =IF(ISBLANK('Order Form'!$O14),"",'Order Form'!$O14) -> 120 Fullness | J14: =IF(ISBLANK('Indetail CAL'!K6),"",'Indetail CAL'!K6) -> 7480
A15: 5 | B15: =IF(ISBLANK('Order Form'!$B15),"",'Order Form'!$B15) -> L1 | C15: =IF(ISBLANK('Order Form'!$C15),"",'Order Form'!$C15) -> 5428 | D15: =IF(ISBLANK('Order Form'!$E15),"",'Order Form'!$E15) -> 2299 | E15: =IF(ISBLANK('Order Form'!M15),"",'Order Form'!M15) -> Single Open | F15: =IF(ISBLANK('Indetail CAL'!$G7),"",'Indetail CAL'!$G7) -> 102 | G15: =IF(ISBLANK('Indetail CAL'!$H7),"",'Indetail CAL'!$H7) | H15: =IF('Indetail CAL'!$I7=0,"",('Indetail CAL'!$I7)) | I15: =IF(ISBLANK('Order Form'!$O15),"",'Order Form'!$O15) -> 140 Fullness | J15: =IF(ISBLANK('Indetail CAL'!K7),"",'Indetail CAL'!K7) -> 12380
A16: 6 | B16: =IF(ISBLANK('Order Form'!$B16),"",'Order Form'!$B16) -> Tv L | C16: =IF(ISBLANK('Order Form'!$C16),"",'Order Form'!$C16) -> 3180 | D16: =IF(ISBLANK('Order Form'!$E16),"",'Order Form'!$E16) -> 2350 | E16: =IF(ISBLANK('Order Form'!M16),"",'Order Form'!M16) -> Single Open | F16: =IF(ISBLANK('Indetail CAL'!$G8),"",'Indetail CAL'!$G8) -> 60 | G16: =IF(ISBLANK('Indetail CAL'!$H8),"",'Indetail CAL'!$H8) | H16: =IF('Indetail CAL'!$I8=0,"",('Indetail CAL'!$I8)) | I16: =IF(ISBLANK('Order Form'!$O16),"",'Order Form'!$O16) -> 144 Fullness | J16: =IF(ISBLANK('Indetail CAL'!K8),"",'Indetail CAL'!K8) -> 7340
A17: 7 | B17: =IF(ISBLANK('Order Form'!$B17),"",'Order Form'!$B17) -> Tv R | C17: =IF(ISBLANK('Order Form'!$C17),"",'Order Form'!$C17) -> 3377 | D17: =IF(ISBLANK('Order Form'!$E17),"",'Order Form'!$E17) -> 2350 | E17: =IF(ISBLANK('Order Form'!M17),"",'Order Form'!M17) -> Single Open | F17: =IF(ISBLANK('Indetail CAL'!$G9),"",'Indetail CAL'!$G9) -> 64 | G17: =IF(ISBLANK('Indetail CAL'!$H9),"",'Indetail CAL'!$H9) | H17: =IF('Indetail CAL'!$I9=0,"",('Indetail CAL'!$I9)) | I17: =IF(ISBLANK('Order Form'!$O17),"",'Order Form'!$O17) -> 120 Fullness | J17: =IF(ISBLANK('Indetail CAL'!K9),"",'Indetail CAL'!K9) -> 7820
A18: 8 | B18: =IF(ISBLANK('Order Form'!$B18),"",'Order Form'!$B18) | C18: =IF(ISBLANK('Order Form'!$C18),"",'Order Form'!$C18) | D18: =IF(ISBLANK('Order Form'!$E18),"",'Order Form'!$E18) | E18: =IF(ISBLANK('Order Form'!M18),"",'Order Form'!M18) | F18: =IF(ISBLANK('Indetail CAL'!$G10),"",'Indetail CAL'!$G10) | G18: =IF(ISBLANK('Indetail CAL'!$H10),"",'Indetail CAL'!$H10) | H18: =IF('Indetail CAL'!$I10=0,"",('Indetail CAL'!$I10)) | I18: =IF(ISBLANK('Order Form'!$O18),"",'Order Form'!$O18) | J18: =IF(ISBLANK('Indetail CAL'!K10),"",'Indetail CAL'!K10)
A19: 9 | B19: =IF(ISBLANK('Order Form'!$B19),"",'Order Form'!$B19) | C19: =IF(ISBLANK('Order Form'!$C19),"",'Order Form'!$C19) | D19: =IF(ISBLANK('Order Form'!$E19),"",'Order Form'!$E19) | E19: =IF(ISBLANK('Order Form'!M19),"",'Order Form'!M19) | F19: =IF(ISBLANK('Indetail CAL'!$G11),"",'Indetail CAL'!$G11) | G19: =IF(ISBLANK('Indetail CAL'!$H11),"",'Indetail CAL'!$H11) | H19: =IF('Indetail CAL'!$I11=0,"",('Indetail CAL'!$I11)) | I19: =IF(ISBLANK('Order Form'!$O19),"",'Order Form'!$O19) | J19: =IF(ISBLANK('Indetail CAL'!K11),"",'Indetail CAL'!K11)
A20: 10 | B20: =IF(ISBLANK('Order Form'!$B20),"",'Order Form'!$B20) | C20: =IF(ISBLANK('Order Form'!$C20),"",'Order Form'!$C20) | D20: =IF(ISBLANK('Order Form'!$E20),"",'Order Form'!$E20) | E20: =IF(ISBLANK('Order Form'!M20),"",'Order Form'!M20) | F20: =IF(ISBLANK('Indetail CAL'!$G12),"",'Indetail CAL'!$G12) | G20: =IF(ISBLANK('Indetail CAL'!$H12),"",'Indetail CAL'!$H12) | H20: =IF('Indetail CAL'!$I12=0,"",('Indetail CAL'!$I12)) | I20: =IF(ISBLANK('Order Form'!$O20),"",'Order Form'!$O20) | J20: =IF(ISBLANK('Indetail CAL'!K12),"",'Indetail CAL'!K12)
A21: 11 | B21: =IF(ISBLANK('Order Form'!$B21),"",'Order Form'!$B21) | C21: =IF(ISBLANK('Order Form'!$C21),"",'Order Form'!$C21) | D21: =IF(ISBLANK('Order Form'!$E21),"",'Order Form'!$E21) | E21: =IF(ISBLANK('Order Form'!M21),"",'Order Form'!M21) | F21: =IF(ISBLANK('Indetail CAL'!$G13),"",'Indetail CAL'!$G13) | G21: =IF(ISBLANK('Indetail CAL'!$H13),"",'Indetail CAL'!$H13) | H21: =IF('Indetail CAL'!$I13=0,"",('Indetail CAL'!$I13)) | I21: =IF(ISBLANK('Order Form'!$O21),"",'Order Form'!$O21) | J21: =IF(ISBLANK('Indetail CAL'!K13),"",'Indetail CAL'!K13)
A22: 12 | B22: =IF(ISBLANK('Order Form'!$B22),"",'Order Form'!$B22) | C22: =IF(ISBLANK('Order Form'!$C22),"",'Order Form'!$C22) | D22: =IF(ISBLANK('Order Form'!$E22),"",'Order Form'!$E22) | E22: =IF(ISBLANK('Order Form'!M22),"",'Order Form'!M22) | F22: =IF(ISBLANK('Indetail CAL'!$G14),"",'Indetail CAL'!$G14) | G22: =IF(ISBLANK('Indetail CAL'!$H14),"",'Indetail CAL'!$H14) | H22: =IF('Indetail CAL'!$I14=0,"",('Indetail CAL'!$I14)) | I22: =IF(ISBLANK('Order Form'!$O22),"",'Order Form'!$O22) | J22: =IF(ISBLANK('Indetail CAL'!K14),"",'Indetail CAL'!K14)
... A26: 16 | B26: =IF(ISBLANK('Order Form'!$B26),"",'Order Form'!$B26) | C26: =IF(ISBLANK('Order Form'!$C26),"",'Order Form'!$C26) | D26: =IF(ISBLANK('Order Form'!$E26),"",'Order Form'!$E26) | E26: =IF(ISBLANK('Order Form'!M26),"",'Order Form'!M26) | F26: =IF(ISBLANK('Indetail CAL'!$G18),"",'Indetail CAL'!$G18) | G26: =IF(ISBLANK('Indetail CAL'!$H18),"",'Indetail CAL'!$H18) | H26: =IF('Indetail CAL'!$I18=0,"",('Indetail CAL'!$I18)) | I26: =IF(ISBLANK('Order Form'!$O26),"",'Order Form'!$O26) | J26: =IF(ISBLANK('Indetail CAL'!K18),"",'Indetail CAL'!K18)
A27: 17 | B27: =IF(ISBLANK('Order Form'!$B27),"",'Order Form'!$B27) | C27: =IF(ISBLANK('Order Form'!$C27),"",'Order Form'!$C27) | D27: =IF(ISBLANK('Order Form'!$E27),"",'Order Form'!$E27) | E27: =IF(ISBLANK('Order Form'!M27),"",'Order Form'!M27) | F27: =IF(ISBLANK('Indetail CAL'!$G35),"",'Indetail CAL'!$G35) | G27: =IF(ISBLANK('Indetail CAL'!$H35),"",'Indetail CAL'!$H35) | H27: =IF('Indetail CAL'!$I35=0,"",('Indetail CAL'!$I35)) | I27: =IF(ISBLANK('Order Form'!$O27),"",'Order Form'!$O27) | J27: =IF(ISBLANK('Indetail CAL'!K35),"",'Indetail CAL'!K35)
A28: 18 | B28: =IF(ISBLANK('Order Form'!$B28),"",'Order Form'!$B28) | C28: =IF(ISBLANK('Order Form'!$C28),"",'Order Form'!$C28) | D28: =IF(ISBLANK('Order Form'!$E28),"",'Order Form'!$E28) | E28: =IF(ISBLANK('Order Form'!M28),"",'Order Form'!M28) | F28: =IF(ISBLANK('Indetail CAL'!$G36),"",'Indetail CAL'!$G36) | G28: =IF(ISBLANK('Indetail CAL'!$H36),"",'Indetail CAL'!$H36) | H28: =IF('Indetail CAL'!$I36=0,"",('Indetail CAL'!$I36)) | I28: =IF(ISBLANK('Order Form'!$O28),"",'Order Form'!$O28) | J28: =IF(ISBLANK('Indetail CAL'!K36),"",'Indetail CAL'!K36)
A29: 19 | B29: =IF(ISBLANK('Order Form'!$B29),"",'Order Form'!$B29) | C29: =IF(ISBLANK('Order Form'!$C29),"",'Order Form'!$C29) | D29: =IF(ISBLANK('Order Form'!$E29),"",'Order Form'!$E29) | E29: =IF(ISBLANK('Order Form'!M29),"",'Order Form'!M29) | F29: =IF(ISBLANK('Indetail CAL'!$G37),"",'Indetail CAL'!$G37) | G29: =IF(ISBLANK('Indetail CAL'!$H37),"",'Indetail CAL'!$H37) | H29: =IF('Indetail CAL'!$I37=0,"",('Indetail CAL'!$I37)) | I29: =IF(ISBLANK('Order Form'!$O29),"",'Order Form'!$O29) | J29: =IF(ISBLANK('Indetail CAL'!K37),"",'Indetail CAL'!K37)
A30: 20 | B30: =IF(ISBLANK('Order Form'!$B30),"",'Order Form'!$B30) | C30: =IF(ISBLANK('Order Form'!$C30),"",'Order Form'!$C30) | D30: =IF(ISBLANK('Order Form'!$E30),"",'Order Form'!$E30) | E30: =IF(ISBLANK('Order Form'!M30),"",'Order Form'!M30) | F30: =IF(ISBLANK('Indetail CAL'!$G38),"",'Indetail CAL'!$G38) | G30: =IF(ISBLANK('Indetail CAL'!$H38),"",'Indetail CAL'!$H38) | H30: =IF('Indetail CAL'!$I38=0,"",('Indetail CAL'!$I38)) | I30: =IF(ISBLANK('Order Form'!$O30),"",'Order Form'!$O30) | J30: =IF(ISBLANK('Indetail CAL'!K38),"",'Indetail CAL'!K38)
